<?xml version="1.0" encoding="utf-8"?>
<robot name="nav_ex">
  <link name="base_link">
    <inertial>
      <origin rpy="0 0 0" xyz="0 0 0" />
      <mass value="0.200000003" />
      <inertia ixx="0.200000002980232" ixy="0" ixz="0" iyy="0.200000002980232" iyz="0" izz="0.200000002980232" />
    </inertial>
    <visual>
      <geometry>
        <box size="0.3 0.15 0.1" />
      </geometry>
    </visual>
    <collision>
      <geometry>
        <box size="0.3 0.15 0.1" />
      </geometry>
    </collision>
  </link>
  <link name="laser_base_link">
    <inertial>
      <origin rpy="0 0 0" xyz="0 0 0" />
      <mass value="0.1000000015" />
      <inertia ixx="0.100000001490116" ixy="0" ixz="0" iyy="0.100000001490116" iyz="0" izz="0.100000001490116" />
    </inertial>
    <visual>
      <origin xyz="0 0 0.025" />
      <geometry>
        <box size="0.05 0.05 0.05" />
      </geometry>
    </visual>
    <collision>
      <origin xyz="0 0 0.025" />
      <geometry>
        <box size="0.05 0.05 0.05" />
      </geometry>
    </collision>
  </link>
  <link name="base_scan_link">
    <inertial>
      <origin rpy="0 0 0" xyz="0 0 0" />
      <mass value="0.1000000015" />
      <inertia ixx="0.100000001490116" ixy="0" ixz="0" iyy="0.100000001490116" iyz="0" izz="0.100000001490116" />
    </inertial>
    <visual>
      <origin xyz="0 0 0.014" />
      <geometry>
        <cylinder length="0.028" radius="0.0229" />
      </geometry>
    </visual>
    <collision>
      <origin xyz="0 0 0.014" />
      <geometry>
        <cylinder length="0.028" radius="0.0229" />
      </geometry>
    </collision>
  </link>
  <link name="back_right_wheel_link">
    <inertial>
      <origin rpy="0 0 0" xyz="0 0 0" />
      <mass value="0.0099999998" />
      <inertia ixx="0.00999999977648258" ixy="0" ixz="0" iyy="0.00999999977648258" iyz="0" izz="0.00999999977648258" />
    </inertial>
    <visual>
      <origin rpy="-4.712389 0 0" />
      <geometry>
        <cylinder length="0.025" radius="0.06" />
      </geometry>
    </visual>
    <collision>
      <origin rpy="-4.712389 0 0" />
      <geometry>
        <cylinder length="0.025" radius="0.06" />
      </geometry>
    </collision>
  </link>
  <link name="back_left_wheel_link">
    <inertial>
      <origin rpy="0 0 0" xyz="0 0 0" />
      <mass value="0.0099999998" />
      <inertia ixx="0.00999999977648258" ixy="0" ixz="0" iyy="0.00999999977648258" iyz="0" izz="0.00999999977648258" />
    </inertial>
    <visual>
      <origin rpy="-4.712389 0 0" />
      <geometry>
        <cylinder length="0.025" radius="0.06" />
      </geometry>
    </visual>
    <collision>
      <origin rpy="-4.712389 0 0" />
      <geometry>
        <cylinder length="0.025" radius="0.06" />
      </geometry>
    </collision>
  </link>
  <link name="front_link">
    <inertial>
      <origin rpy="0 0 0" xyz="0 0 0" />
      <mass value="0.0099999998" />
      <inertia ixx="0.00999999977648258" ixy="0" ixz="0" iyy="0.00999999977648258" iyz="0" izz="0.00999999977648258" />
    </inertial>
    <visual>
      <geometry>
        <box size="0.015 0.15 0.005" />
      </geometry>
    </visual>
    <collision>
      <geometry>
        <box size="0.015 0.15 0.005" />
      </geometry>
    </collision>
  </link>
  <link name="front_right_bar_link">
    <inertial>
      <origin rpy="0 0 0" xyz="0 0 0" />
      <mass value="0.0099999998" />
      <inertia ixx="0.00999999977648258" ixy="0" ixz="0" iyy="0.00999999977648258" iyz="0" izz="0.00999999977648258" />
    </inertial>
    <visual>
      <origin xyz="-0.02 0 0" />
      <geometry>
        <box size="0.03 0.01995 0.005" />
      </geometry>
    </visual>
    <collision>
      <origin xyz="-0.02 0 0" />
      <geometry>
        <box size="0.03 0.01995 0.005" />
      </geometry>
    </collision>
  </link>
  <link name="front_right_wheel_link">
    <inertial>
      <origin rpy="0 0 0" xyz="0 0 0" />
      <mass value="0.0099999998" />
      <inertia ixx="0.00999999977648258" ixy="0" ixz="0" iyy="0.00999999977648258" iyz="0" izz="0.00999999977648258" />
    </inertial>
    <visual>
      <origin rpy="-4.712389 0 0" />
      <geometry>
        <cylinder length="0.025" radius="0.06" />
      </geometry>
    </visual>
    <collision>
      <origin rpy="-4.712389 0 0" />
      <geometry>
        <cylinder length="0.025" radius="0.06" />
      </geometry>
    </collision>
  </link>
  <link name="front_left_bar_link">
    <inertial>
      <origin rpy="0 0 0" xyz="0 0 0" />
      <mass value="0.0099999998" />
      <inertia ixx="0.00999999977648258" ixy="0" ixz="0" iyy="0.00999999977648258" iyz="0" izz="0.00999999977648258" />
    </inertial>
    <visual>
      <origin xyz="-0.02 0 0" />
      <geometry>
        <box size="0.03 0.01995 0.005" />
      </geometry>
    </visual>
    <collision>
      <origin xyz="-0.02 0 0" />
      <geometry>
        <box size="0.03 0.01995 0.005" />
      </geometry>
    </collision>
  </link>
  <link name="front_left_wheel_link">
    <inertial>
      <origin rpy="0 0 0" xyz="0 0 0" />
      <mass value="0.0099999998" />
      <inertia ixx="0.00999999977648258" ixy="0" ixz="0" iyy="0.00999999977648258" iyz="0" izz="0.00999999977648258" />
    </inertial>
    <visual>
      <origin rpy="-4.712389 0 0" />
      <geometry>
        <cylinder length="0.025" radius="0.06" />
      </geometry>
    </visual>
    <collision>
      <origin rpy="-4.712389 0 0" />
      <geometry>
        <cylinder length="0.025" radius="0.06" />
      </geometry>
    </collision>
  </link>
  <link name="steer_link">
    <inertial>
      <origin rpy="0 0 0" xyz="0 0 0" />
      <mass value="0.0099999998" />
      <inertia ixx="0.00999999977648258" ixy="0" ixz="0" iyy="0.00999999977648258" iyz="0" izz="0.00999999977648258" />
    </inertial>
    <visual>
      <origin xyz="-0.02 0 0" />
      <geometry>
        <box size="0.03 0.01995 0.005" />
      </geometry>
    </visual>
    <collision>
      <origin xyz="0.02 0 0" />
      <geometry>
        <box size="0.03 0.01995 0.005" />
      </geometry>
    </collision>
  </link>
  <link name="ackermann_bar_link">
    <inertial>
      <origin rpy="0 0 0" xyz="0 0 0" />
      <mass value="0.0099999998" />
      <inertia ixx="0.00999999977648258" ixy="0" ixz="0" iyy="0.00999999977648258" iyz="0" izz="0.00999999977648258" />
    </inertial>
    <visual>
      <geometry>
        <box size="0.015 0.15 0.01" />
      </geometry>
    </visual>
    <collision>
      <geometry>
        <box size="0.015 0.15 0.01" />
      </geometry>
    </collision>
  </link>
  <joint name="nav_ex_base_link_joint" type="fixed">
    <parent link="nav_ex" />
    <child link="base_link" />
  </joint>
  <joint name="laser_base_mount_joint" type="fixed">
    <origin xyz="0 0 0.05" />
    <parent link="base_link" />
    <child link="laser_base_link" />
  </joint>
  <joint name="base_scan_joint" type="fixed">
    <origin xyz="0 0 0.05" />
    <parent link="laser_base_link" />
    <child link="base_scan_link" />
  </joint>
  <joint name="back_right_wheel_joint" type="continuous">
    <origin xyz="-0.16 -0.1 -0.1" />
    <parent link="base_link" />
    <child link="back_right_wheel_link" />
    <axis xyz="0 1 0" />
  </joint>
  <joint name="back_left_wheel_joint" type="continuous">
    <origin xyz="-0.16 0.1 -0.1" />
    <parent link="base_link" />
    <child link="back_left_wheel_link" />
    <axis xyz="0 1 0" />
  </joint>
  <joint name="front_joint" type="fixed">
    <origin xyz="0.16 0 -0.1" />
    <parent link="base_link" />
    <child link="front_link" />
  </joint>
  <joint name="front_right_bar_joint" type="revolute">
    <origin xyz="0 -0.06 0" />
    <parent link="front_link" />
    <child link="front_right_bar_link" />
    <axis xyz="0 0 1" />
    <limit lower="-0.500000001963219" upper="0.500000001963219" effort="100" velocity="10" />
  </joint>
  <joint name="front_right_wheel_joint" type="continuous">
    <origin xyz="0 -0.04 0" />
    <parent link="front_right_bar_link" />
    <child link="front_right_wheel_link" />
    <axis xyz="0 1 0" />
  </joint>
  <joint name="front_left_bar_joint" type="revolute">
    <origin xyz="0 0.06 0" />
    <parent link="front_link" />
    <child link="front_left_bar_link" />
    <axis xyz="0 0 1" />
    <limit lower="-0.500000001963219" upper="0.500000001963219" effort="100" velocity="10" />
  </joint>
  <joint name="front_left_wheel_joint" type="continuous">
    <origin xyz="0 0.04 0" />
    <parent link="front_left_bar_link" />
    <child link="front_left_wheel_link" />
    <axis xyz="0 1 0" />
  </joint>
  <joint name="steer_joint" type="revolute">
    <parent link="front_link" />
    <child link="steer_link" />
    <axis xyz="0 0 1" />
    <limit lower="-0.500000001963219" upper="0.500000001963219" effort="100" velocity="10" />
  </joint>
  <joint name="ackermann_joint" type="revolute">
    <origin xyz="-0.04 0 0" />
    <parent link="steer_link" />
    <child link="ackermann_bar_link" />
    <axis xyz="0 0 1" />
    <limit lower="-0.500000001963219" upper="0.500000001963219" effort="100" velocity="10" />
  </joint>
  <gazebo reference="base_link">
  <material>Gazebo/Red</material>
</gazebo>
<gazebo reference="front_link">
  <material>Gazebo/Green</material>
</gazebo>
<gazebo reference="steer_link">
  <material>Gazebo/Green</material>
</gazebo>
<gazebo reference="front_left_bar_link">
  <material>Gazebo/Green</material>
</gazebo>
<gazebo reference="front_right_bar_link">
  <material>Gazebo/Green</material>
</gazebo>
<gazebo reference="front_left_wheel_link">
  <material>Gazebo/Green</material>
</gazebo>
<gazebo reference="front_right_wheel_link">
  <material>Gazebo/Green</material>
  <turnGravityOff>false</turnGravityOff>
</gazebo>
<gazebo reference="front_link">
  <material>Gazebo/Green</material>
</gazebo>
<gazebo reference="ackermann_bar_link">
  <material>Gazebo/Blue</material>
</gazebo>
<gazebo>
  <joint:hinge name="ackermann_left_bar_joint" xmlns:joint="http://playerstage.sourceforge.net/gazebo/xmlschema/#joint">
    <body1>ackermann_bar_link</body1>
    <body2>front_left_bar_link</body2>
    <anchor>ackermann_bar_link</anchor>
    <axis>0 0 1</axis>
    <anchorOffset>0 0.06 0</anchorOffset>
  </joint:hinge>
</gazebo>
<gazebo>
  <joint:hinge name="ackermann_right_bar_joint" xmlns:joint="http://playerstage.sourceforge.net/gazebo/xmlschema/#joint">
    <body1>ackermann_bar_link</body1>
    <body2>front_right_bar_link</body2>
    <anchor>ackermann_bar_link</anchor>
    <axis>0 0 1</axis>
    <anchorOffset>0 -0.06 0</anchorOffset>
  </joint:hinge>
</gazebo>
<gazebo reference="back_left_wheel_link">
  <material>Gazebo/Black</material>
</gazebo>
<gazebo reference="back_right_wheel_link">
  <material>Gazebo/Black</material>
</gazebo>
<gazebo>
  <controller:ackermann_plugin name="ackermann_controller" plugin="libackermann_plugin.so" xmlns:controller="http://playerstage.sourceforge.net/gazebo/xmlschema/#controller">
    <alwaysOn>true</alwaysOn>
    <update>100</update>
    <updateRate>100.0</updateRate>
    <leftJoint>back_left_wheel_joint</leftJoint>
    <rightJoint>back_right_wheel_joint</rightJoint>
    <steerJoint>steer_joint</steerJoint>
    <wheelSeparationWidth>0.16</wheelSeparationWidth>
    <wheelSeparationLength>0.32</wheelSeparationLength>
    <wheelDiameter>0.041</wheelDiameter>
    <driveTorque>5</driveTorque>
    <steerTorque>5</steerTorque>
    <interface:position name="position_iface_0" xmlns:interface="http://playerstage.sourceforge.net/gazebo/xmlschema/#interface" />
    <robotNamespace>/</robotNamespace>
    <topicName>pilot/drive</topicName>
  </controller:ackermann_plugin>
  <canonicalBody>base_footprint</canonicalBody>
  <!-- this publishes empty joint_states due to no transmission, but
    triggering robot_state_publisher to publish tf between fixed joints in erratic,
    (e.g. base_laser_link for the base_scan frame) -->
  <controller:gazebo_ros_controller_manager name="gazebo_ros_controller_manager" plugin="libgazebo_ros_controller_manager.so" xmlns:controller="http://playerstage.sourceforge.net/gazebo/xmlschema/#controller">
    <alwaysOn>true</alwaysOn>
    <updateRate>100.0</updateRate>
    <interface:audio name="gazebo_ros_controller_manager_dummy_iface" xmlns:interface="http://playerstage.sourceforge.net/gazebo/xmlschema/#interface" />
  </controller:gazebo_ros_controller_manager>
</gazebo>
<gazebo reference="base_scan_link">
  <sensor:ray name="laser" xmlns:sensor="http://playerstage.sourceforge.net/gazebo/xmlschema/#sensor">
    <rayCount>683</rayCount>
    <rangeCount>683</rangeCount>
    <laserCount>1</laserCount>
    <origin>0.0 0.0 0.0</origin>
    <displayRays>false</displayRays>
    <minAngle>-135</minAngle>
    <maxAngle> 135</maxAngle>
    <minRange>0.06</minRange>
    <maxRange>4.0</maxRange>
    <resRange>0.001</resRange>
    <updateRate>10.0</updateRate>
    <controller:gazebo_ros_laser name="gazebo_ros_base_scan_link_controller" plugin="libgazebo_ros_laser.so" xmlns:controller="http://playerstage.sourceforge.net/gazebo/xmlschema/#controller">
      <gaussianNoise>0.005</gaussianNoise>
      <alwaysOn>true</alwaysOn>
      <updateRate>10.0</updateRate>
      <topicName>base_scan/scan</topicName>
      <frameName>base_scan_link</frameName>
      <interface:laser name="gazebo_ros_base_scan_link_iface" xmlns:interface="http://playerstage.sourceforge.net/gazebo/xmlschema/#interface" />
    </controller:gazebo_ros_laser>
  </sensor:ray>
</gazebo>
<gazebo reference="laser_base_link">
  <material>Gazebo/Black</material>
</gazebo>
<gazebo reference="base_scan_link">
  <material>Gazebo/Black</material>
</gazebo>
</robot>