<?xml version="1.0" ?>
<!-- =================================================================================== -->
<!-- |    This document was autogenerated by xacro from car.urdf.xacro                 | -->
<!-- |    EDITING THIS FILE BY HAND IS NOT RECOMMENDED                                 | -->
<!-- =================================================================================== -->
<robot name="robot0516" >
  <!-- Physical Constant Macros -->
  <!-- Dimension Macros -->
  <!-- Physical Material Macros -->
  <material name="Red">
    <color rgba="1.0 0 0 1.0"/>
  </material>
  <material name="Green">
    <color rgba="0 1.0 0 1.0"/>
  </material>
  <material name="Blue">
    <color rgba="0 0 1.0 0.5"/>
  </material>
  <material name="Black">
    <color rgba="0 0 0 1.0"/>
  </material>
  <material name="Aqua">
    <color rgba="0 255 255 1.0"/>
  </material>
  <material name="black">
    <color rgba="0 0 0 1"/>
  </material>
   <material name="white">
    <color rgba="1 1 1 1"/>
  </material>
  <!-- Main body -->
  <link name="base_link">
    <inertial>
      <mass value="70"/>
      <origin xyz="0 0 0"/>
      <inertia ixx="7.29.0" ixy="0.0" ixz="0.0" iyy="10.0479" iyz="0.0" izz="5.672"/>
    </inertial>
    <visual>
      <origin rpy="0 0 0" xyz="0 0 0"/>
      <geometry>
        <box size="0.85 0.5 1"/>
      </geometry>
      <material name="Red"/>
    </visual>
    <collision>
      <origin rpy="0 0 0" xyz="0 0 0"/>
      <geometry>
        <box size="0.85 0.5 1"/>
      </geometry>
    </collision>
  </link>
  <!-- Front link of Ackermann -->
  <!-- Joins to the Car body -->
  <joint name="front_joint" type="fixed">
    <parent link="base_link"/>
    <child link="front_link"/>
    <origin xyz="0.5 0 -0.8"/>
  </joint>
  <link name="front_link">
    <inertial>
      <mass value="10"/>
      <origin xyz="0 0 0"/>
      <inertia ixx="5.0" ixy="0.0" ixz="0.0" iyy="5.0" iyz="0.0" izz="5.0"/>
    </inertial>
    <visual>
      <geometry>
        <box size="0.04 0.5 0.05"/>
      </geometry>
      <material name="Aqua"/>
    </visual>
    <collision>
      <geometry>
        <box size="0.04 0.5 0.05"/>
      </geometry>
    </collision>
  </link>
  <!-- a link aligned with the steer direction -->
  <joint name="steer_joint" type="revolute">
    <limit effort="5000" lower="-0.5" upper="0.5" velocity="10"/>
    <axis xyz="0 0 1"/>
    <parent link="front_link"/>
    <child link="steer_link"/>
    <origin rpy="0 0 0" xyz="0.0 0.0 0.0"/>
  </joint>
  <link name="steer_link">
    <inertial>
      <mass value="4.0"/>
      <origin xyz="0 0 0"/>
      <inertia ixx="3.0" ixy="0.0" ixz="0.0" iyy="3.0" iyz="0.0" izz="3.0"/>
    </inertial>
    <visual>
      <origin xyz="-0.06 0 0"/>
      <geometry>
        <box size="0.16 0.06 0.05"/>
      </geometry>
      <material name="Green"/>
    </visual>
    <collision>
      <origin xyz="-0.06 0 0"/>
      <geometry>
        <box size="0.16 0.06 0.05"/>
      </geometry>
    </collision>
  </link>
  <!-- the left Ackermann bar -->
  <joint name="front_left_bar_joint" type="revolute">
    <limit effort="5000" lower="-0.5" upper="0.5" velocity="10"/>
    <axis xyz="0 0 1"/>
    <parent link="front_link"/>
    <child link="front_left_bar_link"/>
    <origin rpy="0 0 0" xyz="0.0 0.22 0.0"/>
  </joint>
  <link name="front_left_bar_link">
    <inertial>
      <mass value="4.0"/>
      <origin xyz="0 0 0"/>
      <inertia ixx="3.0" ixy="0.0" ixz="0.0" iyy="3.0" iyz="0.0" izz="3.0"/>
    </inertial>
    <visual>
      <origin xyz="-0.06 0 0"/>
      <geometry>
        <box size="0.16 0.06 0.05"/>
      </geometry>
      <material name="Green"/>
    </visual>
    <collision>
      <origin xyz="-0.06 0 0"/>
      <geometry>
        <box size="0.16 0.06 0.05"/>
      </geometry>
    </collision>
  </link>
  <!-- the right Ackermann bar -->
  <joint name="front_right_bar_joint" type="revolute">
    <limit effort="1000" lower="-0.5" upper="0.5" velocity="10"/>
    <axis xyz="0 0 1"/>
    <parent link="front_link"/>
    <child link="front_right_bar_link"/>
    <origin rpy="0 0 0" xyz="0.0 -0.22 0.0"/>
  </joint>
  <link name="front_right_bar_link">
    <inertial>
      <mass value="4.0"/>
      <origin xyz="0 0 0"/>
      <inertia ixx="3.0" ixy="0.0" ixz="0.0" iyy="3.0" iyz="0.0" izz="3.0"/>
    </inertial>
    <visual>
      <origin xyz="-0.06 0 0"/>
      <geometry>
        <box size="0.16 0.06 0.05"/>
      </geometry>
      <material name="Green"/>
    </visual>
    <collision>
      <origin xyz="-0.06 0 0"/>
      <geometry>
        <box size="0.16 0.06 0.05"/>
      </geometry>
    </collision>
  </link>
  <!-- the front left wheel -->
  <joint name="front_left_wheel_joint" type="continuous">
    <axis xyz="0 1 0"/>
    <parent link="front_left_bar_link"/>
    <child link="front_left_wheel_link"/>
    <origin rpy="0 0 0" xyz="0 0.2 0"/>
  </joint>
  <link name="front_left_wheel_link">
    <inertial>
      <mass value="5.0"/>
      <origin xyz="0 0 0"/>
      <inertia ixx="3.0" ixy="0.0" ixz="3.0" iyy="0.00" iyz="0.0" izz="3.0"/>
    </inertial>
    <visual>
      <origin rpy="1.57079632679 0 0" xyz="0 0 0"/>
      <geometry>
        <cylinder length="0.1" radius="0.15"/>
      </geometry>
      <material name="Green"/>
    </visual>
    <collision>
      <origin rpy="1.57079632679 0 0" xyz="0 0 0"/>
      <geometry>
        <cylinder length="0.1" radius="0.15"/>
      </geometry>
    </collision>
  </link>
  <!-- the front right wheel -->
  <joint name="front_right_wheel_joint" type="continuous">
    <axis xyz="0 1 0"/>
    <parent link="front_right_bar_link"/>
    <child link="front_right_wheel_link"/>
    <origin rpy="0 0 0" xyz="0 -0.1 0"/>
  </joint>
  <link name="front_right_wheel_link">
    <inertial>
      <mass value="4.0"/>
      <origin xyz="0 0 0"/>
      <inertia ixx="3.0" ixy="0.0" ixz="0.0" iyy="3.0" iyz="0.0" izz="3.0"/>
    </inertial>
    <visual>
      <origin rpy="1.57079632679 0 0" xyz="0 0 0"/>
      <geometry>
        <cylinder length="0.1" radius="0.15"/>
      </geometry>
      <material name="Green"/>
    </visual>
    <collision>
      <origin rpy="1.57079632679 0 0" xyz="0 0 0"/>
      <geometry>
        <cylinder length="0.1" radius="0.15"/>
      </geometry>
    </collision>
  </link>
  <!-- the Ackerman bar -->
  <joint name="ackermann_joint" type="revolute">
    <limit effort="3000" lower="-0.5" upper="0.5" velocity="10"/>
    <axis xyz="0 0 1"/>
    <parent link="steer_link"/>
    <child link="ackermann_bar_link"/>
    <origin rpy="0 0 0" xyz="-0.12 0 0"/>
  </joint>
  <link name="ackermann_bar_link">
    <inertial>
      <mass value="4.0"/>
      <origin xyz="0 0 0"/>
      <inertia ixx="3.0" ixy="0.0" ixz="0.0" iyy="3.0" iyz="0.0" izz="3.0"/>
    </inertial>
    <visual>
      <geometry>
        <box size="0.04 0.5 0.05"/>
      </geometry>
      <material name="Green"/>
    </visual>
    <collision>
      <geometry>
        <box size="0.04 0.5 0.05"/>
      </geometry>
    </collision>
  </link>
  <!-- the back left wheel -->
  <joint name="back_left_wheel_joint" type="continuous">
    <axis xyz="0 1 0"/>
    <parent link="base_link"/>
    <child link="back_left_wheel_link"/>
    <origin rpy="0 0 0" xyz="-0.35 0.32 -0.6"/>
  </joint>
  <link name="back_left_wheel_link">
    <inertial>
      <mass value="1.0"/>
      <origin xyz="0 0 0"/>
      <inertia ixx="1.0" ixy="0.0" ixz="1.0" iyy="0.01" iyz="0.0" izz="1.0"/>
    </inertial>
    <visual>
      <origin rpy="1.57079632679 0 0" xyz="0 0 0"/>
      <geometry>
        <cylinder length="0.05" radius="0.15"/>
      </geometry>
      <material name="Black"/>
    </visual>
    <collision>
      <origin rpy="1.57079632679 0 0" xyz="0 0 0"/>
      <geometry>
        <cylinder length="0.05" radius="0.15"/>
      </geometry>
    </collision>
  </link>
  <!-- the back right weel -->
  <joint name="back_right_wheel_joint" type="continuous">
    <axis xyz="0 1 0"/>
    <parent link="base_link"/>
    <child link="back_right_wheel_link"/>
    <origin rpy="0 0 0" xyz="-0.35 -0.32 -0.6"/>
  </joint>
  <link name="back_right_wheel_link">
    <inertial>
      <mass value="1.0"/>
      <origin xyz="0 0 0"/>
      <inertia ixx="1.0" ixy="0.0" ixz="0.0" iyy="1.0" iyz="0.0" izz="1.0"/>
    </inertial>
    <visual>
      <origin rpy="1.57079632679 0 0" xyz="0 0 0"/>
      <geometry>
        <cylinder length="0.05" radius="0.15"/>
      </geometry>
      <material name="Black"/>
    </visual>
    <collision>
      <origin rpy="1.57079632679 0 0" xyz="0 0 0"/>
      <geometry>
        <cylinder length="0.05" radius="0.15"/>
      </geometry>
    </collision>
  </link>
</robot>
